<sdf version='1.7'>
  <model name='bipedal_walker'>
    <joint name='grounding' type='fixed'>
      <pose relative_to='__model__'>0 0 0 0 -0 0</pose>
      <parent>world</parent>
      <child>outer_ring</child>
    </joint>
    <link name='outer_ring'>
      <pose relative_to='grounding'>0 0 0 0 -0 0</pose>
      <inertial>
        <pose>0 0 0.165 0 -0 0</pose>
        <mass>0.49244</mass>
        <inertia>
          <ixx>0.00502601</ixx>
          <ixy>-1.62359e-35</ixy>
          <ixz>7.47909e-35</ixz>
          <iyy>0.00502601</iyy>
          <iyz>-2.39524e-19</iyz>
          <izz>0.00111416</izz>
        </inertia>
      </inertial>
      <collision name='outer_ring_collision'>
        <pose>0 0 0 1.5708 -0 0</pose>
        <geometry>
          <mesh>
            <scale>1 1 1</scale>
            <uri>model://walker_sim/meshes/outter_ring.STL</uri>
          </mesh>
        </geometry>
      </collision>
    </link>
    <joint name='outer_ring_inner_ring' type='prismatic'>
      <pose relative_to='outer_ring'>0 0 0.33 0 -0 0</pose>
      <parent>outer_ring</parent>
      <child>inner_ring</child>
      <axis>
        <xyz>0 -1 0</xyz>
        <limit>
          <lower>0</lower>
          <upper>10</upper>
          <effort>30</effort>
          <velocity>7</velocity>
        </limit>
        <dynamics>
          <damping>0</damping>
          <friction>0</friction>
          <spring_reference>0</spring_reference>
          <spring_stiffness>0</spring_stiffness>
        </dynamics>
      </axis>
    </joint>
    <link name='inner_ring'>
      <pose relative_to='outer_ring_inner_ring'>0 0 0 0 -0 0</pose>
      <inertial>
        <pose>0.103871 0 0.055001 0 -0 0</pose>
        <mass>0.60401</mass>
        <inertia>
          <ixx>0.00103169</ixx>
          <ixy>-1.58892e-19</ixy>
          <ixz>-0.00303878</ixz>
          <iyy>0.0243557</iyy>
          <iyz>-2.8431e-21</iyz>
          <izz>0.0237514</izz>
        </inertia>
      </inertial>
      <collision name='inner_ring_collision'>
        <pose>0 0 0 1.5708 -0 0</pose>
        <geometry>
          <mesh>
            <scale>1 1 1</scale>
            <uri>model://walker_sim/meshes/inner_ring.STL</uri>
          </mesh>
        </geometry>
      </collision>
      <collision name='inner_ring_fixed_joint_lump__boom_collision_1'>
        <pose>0 0 0.08 1.5708 -0 0</pose>
        <geometry>
          <mesh>
            <scale>1 1 1</scale>
            <uri>model://walker_sim/meshes/boom_horizontal.STL</uri>
          </mesh>
        </geometry>
        <surface>
          <contact>
            <ode/>
          </contact>
          <friction>
            <ode/>
          </friction>
        </surface>
      </collision>
    </link>
    <joint name='boom_waist' type='prismatic'>
      <pose relative_to='inner_ring'>0.725 0 0.08 0 -0 0</pose>
      <parent>inner_ring</parent>
      <child>waist</child>
      <axis>
        <xyz>0 0 1</xyz>
        <limit>
          <lower>-0.5</lower>
          <upper>0.5</upper>
          <effort>30</effort>
          <velocity>7</velocity>
        </limit>
        <dynamics>
          <damping>0</damping>
          <friction>0</friction>
          <spring_reference>0</spring_reference>
          <spring_stiffness>0</spring_stiffness>
        </dynamics>
      </axis>
    </joint>
    <link name='waist'>
      <pose relative_to='boom_waist'>0 0 0 0 -0 0</pose>
      <inertial>
        <pose>-0 -0.006634 0.024451 0 -0 0</pose>
        <mass>0.36416</mass>
        <inertia>
          <ixx>0.0011236</ixx>
          <ixy>1.20595e-19</ixy>
          <ixz>1.11224e-20</ixz>
          <iyy>0.00100247</iyy>
          <iyz>0.000103236</iyz>
          <izz>0.00193096</izz>
        </inertia>
      </inertial>
      <collision name='waist_collision'>
        <pose>0 0 0 1.5708 -0 0</pose>
        <geometry>
          <mesh>
            <scale>1 1 1</scale>
            <uri>model://walker_sim/meshes/waist_L.STL</uri>
          </mesh>
        </geometry>
        <surface>
          <contact>
            <ode/>
          </contact>
          <friction>
            <ode/>
          </friction>
        </surface>
      </collision>
      <visual name='waist_visual'>
        <pose>0 0 0 1.5708 -0 0</pose>
        <geometry>
          <mesh>
            <scale>1 1 1</scale>
            <uri>model://walker_sim/meshes/waist_L.STL</uri>
          </mesh>
        </geometry>
        <material>
          <script>
            <name>Gazebo/Turquoise</name>
            <uri>file://media/materials/scripts/gazebo.material</uri>
          </script>
        </material>
      </visual>
    </link>
    <joint name='waist_thighL' type='revolute'>
      <pose relative_to='waist'>0.0775 0 0 0 -0 0</pose>
      <parent>waist</parent>
      <child>thighL</child>
      <axis>
        <xyz>1 0 0</xyz>
        <limit>
          <lower>-0.8</lower>
          <upper>0.8</upper>
          <effort>30</effort>
          <velocity>7</velocity>
        </limit>
        <dynamics>
          <spring_reference>0</spring_reference>
          <spring_stiffness>0</spring_stiffness>
        </dynamics>
      </axis>
    </joint>
    <link name='thighL'>
      <pose relative_to='waist_thighL'>0 0 0 0 -0 0</pose>
      <inertial>
        <pose>7.1e-05 -0 -0.095855 0 -0 0</pose>
        <mass>0.045155</mass>
        <inertia>
          <ixx>0.000160299</ixx>
          <ixy>2.81502e-13</ixy>
          <ixz>8.0193e-08</ixz>
          <iyy>0.000161034</iyy>
          <iyz>-1.20372e-13</iyz>
          <izz>5.91731e-06</izz>
        </inertia>
      </inertial>
      <collision name='thighL_collision'>
        <pose>0 0 0 1.5708 -0 0</pose>
        <geometry>
          <mesh>
            <scale>1 1 1</scale>
            <uri>model://walker_sim/meshes/31mar/thigh.STL</uri>
          </mesh>
        </geometry>
        <surface>
          <contact>
            <ode/>
          </contact>
          <friction>
            <ode/>
          </friction>
        </surface>
      </collision>
      <visual name='thighL_visual'>
        <pose>0 0 0 1.5708 -0 0</pose>
        <geometry>
          <mesh>
            <scale>1 1 1</scale>
            <uri>model://walker_sim/meshes/thigh.STL</uri>
          </mesh>
        </geometry>
        <material>
          <script>
            <name>Gazebo/White</name>
            <uri>file://media/materials/scripts/gazebo.material</uri>
          </script>
        </material>
      </visual>
    </link>
    <joint name='thighL_shankL' type='revolute'>
      <pose relative_to='thighL'>0 0 -0.19 0 -0 0</pose>
      <parent>thighL</parent>
      <child>shankL</child>
      <axis>
        <xyz>1 0 0</xyz>
        <limit>
          <lower>-0.00118981</lower>
          <upper>1.4</upper>
          <effort>30</effort>
          <velocity>7</velocity>
        </limit>
        <dynamics>
          <spring_reference>0</spring_reference>
          <spring_stiffness>0</spring_stiffness>
        </dynamics>
      </axis>
    </joint>
    <link name='shankL'>
      <pose relative_to='thighL_shankL'>0 0 0 0 -0 0</pose>
      <inertial>
        <pose>-0 -0 -0.099607 0 -0 0</pose>
        <mass>0.0793255</mass>
        <inertia>
          <ixx>0.000329398</ixx>
          <ixy>6.48339e-13</ixy>
          <ixz>1.95605e-10</ixz>
          <iyy>0.000329563</iyy>
          <iyz>-8.67791e-10</iyz>
          <izz>5.35098e-06</izz>
        </inertia>
      </inertial>
      <collision name='shankL_collision'>
        <pose>0 0 0 1.5708 -0 0</pose>
        <geometry>
          <mesh>
            <scale>1 1 1</scale>
            <uri>model://walker_sim/meshes/shank.STL</uri>
          </mesh>
        </geometry>
        <surface>
          <contact>
            <ode/>
          </contact>
          <friction>
            <ode/>
          </friction>
        </surface>
      </collision>
      <collision name='shankL_fixed_joint_lump__footL_collision_1'>
        <pose>0 0 -0.175 1.5708 -0 0</pose>
        <geometry>
          <mesh>
            <scale>1 1 1</scale>
            <uri>model://walker_sim/meshes/contact_sensor.STL</uri>
          </mesh>
        </geometry>
        <surface>
          <contact>
            <ode/>
          </contact>
          <friction>
            <ode/>
          </friction>
        </surface>
      </collision>
      <visual name='shankL_visual'>
        <pose>0 0 0 1.5708 -0 0</pose>
        <geometry>
          <mesh>
            <scale>1 1 1</scale>
            <uri>model://walker_sim/meshes/shank.STL</uri>
          </mesh>
        </geometry>
        <material>
          <script>
            <name>Gazebo/White</name>
            <uri>file://media/materials/scripts/gazebo.material</uri>
          </script>
        </material>
      </visual>
      <visual name='shankL_fixed_joint_lump__footL_visual_1'>
        <pose>0 0 -0.175 1.5708 -0 0</pose>
        <geometry>
          <mesh>
            <scale>1 1 1</scale>
            <uri>model://walker_sim/meshes/contact_sensor.STL</uri>
          </mesh>
        </geometry>
        <material>
          <script>
            <name>Gazebo/Black</name>
            <uri>file://media/materials/scripts/gazebo.material</uri>
          </script>
        </material>
      </visual>
      <sensor name='footL_contact_sensor' type='contact'>
        <always_on>1</always_on>
        <update_rate>120</update_rate>
        <contact>
          <collision>shankL_collision_footL</collision>
          <topic>__default_topic__</topic>
        </contact>
        <plugin name='gazebo_ros_bumper_controller' filename='libgazebo_ros_bumper.so'>
          <bumperTopicName>/footL_contact_sensor_state</bumperTopicName>
          <frameName>footL</frameName>
          <robotNamespace>/walker</robotNamespace>
        </plugin>
        <pose>0 0 -0.175 0 -0 0</pose>
      </sensor>
    </link>
    <joint name='waist_thighR' type='revolute'>
      <pose relative_to='waist'>-0.0775 0 0 0 -0 0</pose>
      <parent>waist</parent>
      <child>thighR</child>
      <axis>
        <xyz>1 0 0</xyz>
        <limit>
          <lower>-0.8</lower>
          <upper>0.8</upper>
          <effort>30</effort>
          <velocity>7</velocity>
        </limit>
        <dynamics>
          <spring_reference>0</spring_reference>
          <spring_stiffness>0</spring_stiffness>
        </dynamics>
      </axis>
    </joint>
    <link name='thighR'>
      <pose relative_to='waist_thighR'>0 0 0 0 -0 0</pose>
      <inertial>
        <pose>7.1e-05 -0 -0.095855 0 -0 0</pose>
        <mass>0.045155</mass>
        <inertia>
          <ixx>0.000160299</ixx>
          <ixy>2.81502e-13</ixy>
          <ixz>8.0193e-08</ixz>
          <iyy>0.000161034</iyy>
          <iyz>-1.20372e-13</iyz>
          <izz>5.91731e-06</izz>
        </inertia>
      </inertial>
      <collision name='thighR_collision'>
        <pose>0 0 0 1.5708 -0 0</pose>
        <geometry>
          <mesh>
            <scale>1 1 1</scale>
            <uri>model://walker_sim/meshes/thigh.STL</uri>
          </mesh>
        </geometry>
        <surface>
          <contact>
            <ode/>
          </contact>
          <friction>
            <ode/>
          </friction>
        </surface>
      </collision>
      <visual name='thighR_visual'>
        <pose>0 0 0 1.5708 -0 0</pose>
        <geometry>
          <mesh>
            <scale>1 1 1</scale>
            <uri>model://walker_sim/meshes/thigh.STL</uri>
          </mesh>
        </geometry>
        <material>
          <script>
            <name>Gazebo/White</name>
            <uri>file://media/materials/scripts/gazebo.material</uri>
          </script>
        </material>
      </visual>
    </link>
    <joint name='thighR_shankR' type='revolute'>
      <pose relative_to='thighR'>0 0 -0.19 0 -0 0</pose>
      <parent>thighR</parent>
      <child>shankR</child>
      <axis>
        <xyz>1 0 0</xyz>
        <limit>
          <lower>-0.00118981</lower>
          <upper>1.4</upper>
          <effort>30</effort>
          <velocity>7</velocity>
        </limit>
        <dynamics>
          <spring_reference>0</spring_reference>
          <spring_stiffness>0</spring_stiffness>
        </dynamics>
      </axis>
    </joint>
    <link name='shankR'>
      <pose relative_to='thighR_shankR'>0 0 0 0 -0 0</pose>
      <inertial>
        <pose>-0 -0 -0.099607 0 -0 0</pose>
        <mass>0.0793255</mass>
        <inertia>
          <ixx>0.000329398</ixx>
          <ixy>6.48339e-13</ixy>
          <ixz>1.95605e-10</ixz>
          <iyy>0.000329563</iyy>
          <iyz>-8.67791e-10</iyz>
          <izz>5.35098e-06</izz>
        </inertia>
      </inertial>
      <collision name='shankR_collision'>
        <pose>0 0 0 1.5708 -0 0</pose>
        <geometry>
          <mesh>
            <scale>1 1 1</scale>
            <uri>model://walker_sim/meshes/shank.STL</uri>
          </mesh>
        </geometry>
        <surface>
          <contact>
            <ode/>
          </contact>
          <friction>
            <ode/>
          </friction>
        </surface>
      </collision>
      <collision name='shankR_fixed_joint_lump__footR_collision_1'>
        <pose>0 0 -0.175 1.5708 -0 0</pose>
        <geometry>
          <mesh>
            <scale>1 1 1</scale>
            <uri>model://walker_sim/meshes/contact_sensor.STL</uri>
          </mesh>
        </geometry>
        <surface>
          <contact>
            <ode/>
          </contact>
          <friction>
            <ode/>
          </friction>
        </surface>
      </collision>
      <visual name='shankR_visual'>
        <pose>0 0 0 1.5708 -0 0</pose>
        <geometry>
          <mesh>
            <scale>1 1 1</scale>
            <uri>model://walker_sim/meshes/shank.STL</uri>
          </mesh>
        </geometry>
        <material>
          <script>
            <name>Gazebo/White</name>
            <uri>file://media/materials/scripts/gazebo.material</uri>
          </script>
        </material>
      </visual>
      <visual name='shankR_fixed_joint_lump__footR_visual_1'>
        <pose>0 0 -0.175 1.5708 -0 0</pose>
        <geometry>
          <mesh>
            <scale>1 1 1</scale>
            <uri>model://walker_sim/meshes/contact_sensor.STL</uri>
          </mesh>
        </geometry>
        <material>
          <script>
            <name>Gazebo/Black</name>
            <uri>file://media/materials/scripts/gazebo.material</uri>
          </script>
        </material>
      </visual>
      <sensor name='footR_contact_sensor' type='contact'>
        <always_on>1</always_on>
        <update_rate>120</update_rate>
        <contact>
          <collision>shankR_collision_footR</collision>
          <topic>__default_topic__</topic>
        </contact>
        <plugin name='gazebo_ros_bumper_controller_1' filename='libgazebo_ros_bumper.so'>
          <bumperTopicName>/footR_contact_sensor_state</bumperTopicName>
          <frameName>footR</frameName>
          <robotNamespace>/walker</robotNamespace>
        </plugin>
        <pose>0 0 -0.175 0 -0 0</pose>
      </sensor>
    </link>
    <static>0</static>
    <plugin name='gazebo_ros_control' filename='libgazebo_ros_control.so'>
      <robotNamespace>/walker</robotNamespace>
    </plugin>
  </model>
</sdf>
